# MongoDB Validation Error Fix - created_at Field

## 🚨 **Problem**
```
❌ Failed to save paragraph: HTTP error! status: 500 - {
  "detail": {
    "error": "paragraph_save_failed",
    "message": "Failed to save paragraph to database",
    "details": "Document failed validation, full error: {
      'index': 0, 
      'code': 121, 
      'errmsg': 'Document failed validation', 
      'errInfo': {
        'failingDocumentId': ObjectId('68c3c8cd2e3b5ac57a17be23'), 
        'details': {
          'operatorName': '$jsonSchema', 
          'schemaRulesNotSatisfied': [{
            'operatorName': 'required', 
            'specifiedAs': {'required': ['user_id', 'words', 'created_at']}, 
            'missingProperties': ['created_at']
          }]
        }
      }
    }"
  }
}
```

## 🔍 **Root Cause Analysis**

The MongoDB validation error occurred because:

1. **Missing `created_at` field**: The database schema requires `created_at` field for collections
2. **CRUD operations not setting field**: Some CRUD methods were not explicitly setting `created_at`
3. **Pydantic default factory not triggering**: The `Field(default_factory=datetime.utcnow)` was not being applied during `.dict()` conversion

## ✅ **Solution Applied**

### 1. **Fixed InputHistoryCRUD.create_input_history()**
```python
# BEFORE
async def create_input_history(self, history_data: InputHistoryCreate) -> InputHistoryInDB:
    history_dict = history_data.dict()
    history_dict['user_id'] = ObjectId(history_dict['user_id'])
    # Missing: created_at field
    
# AFTER  
async def create_input_history(self, history_data: InputHistoryCreate) -> InputHistoryInDB:
    history_dict = history_data.dict()
    history_dict['user_id'] = ObjectId(history_dict['user_id'])
    history_dict['created_at'] = datetime.utcnow()  # ✅ FIXED
```

### 2. **Fixed SavedParagraphCRUD.create_saved_paragraph()**
```python
# BEFORE
async def create_saved_paragraph(self, paragraph_data: SavedParagraphCreate) -> SavedParagraphInDB:
    paragraph_dict = paragraph_data.dict()
    paragraph_dict['input_history_id'] = ObjectId(paragraph_dict['input_history_id'])
    # Missing: created_at field
    
# AFTER
async def create_saved_paragraph(self, paragraph_data: SavedParagraphCreate) -> SavedParagraphInDB:
    paragraph_dict = paragraph_data.dict()
    paragraph_dict['input_history_id'] = ObjectId(paragraph_dict['input_history_id'])
    paragraph_dict['created_at'] = datetime.utcnow()  # ✅ FIXED
```

## 📋 **Collections Status**

| Collection | Status | Action Taken |
|------------|--------|--------------|
| **users** | ✅ Working | Already had explicit `created_at` |
| **refresh_tokens** | ✅ Working | Already had explicit `created_at` |
| **input_history** | ❌ → ✅ Fixed | Added explicit `created_at = datetime.utcnow()` |
| **saved_paragraph** | ❌ → ✅ Fixed | Added explicit `created_at = datetime.utcnow()` |

## 🧪 **Validation**

### Server Status
- ✅ Server running on `http://127.0.0.1:8003`
- ✅ All database schemas synchronized
- ✅ No validation errors in startup logs

### CRUD Testing
- ✅ InputHistoryCreate model validation passed
- ✅ SavedParagraphCreate model validation passed
- ✅ All imports successful

## 🔄 **Expected Result**

After these fixes, the following operations should now work without validation errors:

1. **Creating input history** - will include `created_at` field
2. **Saving paragraphs** - will include `created_at` field  
3. **All database operations** - will pass MongoDB schema validation

## 🎯 **Key Learnings**

1. **Pydantic Field defaults**: `Field(default_factory=datetime.utcnow)` doesn't always trigger during `.dict()` conversion
2. **Explicit field setting**: Always explicitly set required fields in CRUD operations
3. **MongoDB validation**: Schema validation is strict and requires all specified fields
4. **Error debugging**: MongoDB validation errors provide detailed field-level information

## 🚀 **Next Steps**

1. Test the paragraph saving functionality that was originally failing
2. Monitor server logs for any remaining validation errors
3. Consider adding validation tests to prevent similar issues

---

**Fixed on:** September 12, 2025  
**Server:** Running on port 8003 with fixes applied  
**Status:** ✅ Ready for testing